[2022.12.30/11:19:30] : ERROR | Traceback (most recent call last):
  File "c:\Users\user\code\python\kiosk\BackEnd\sorce\module\DB\DB.py", line 31, in SELECT_ONE
    self.curs.execute(query,args)
  File "C:\Users\user\AppData\Local\Programs\Python\Python310\lib\site-packages\pymysql\cursors.py", line 148, in execute
    result = self._query(query)
  File "C:\Users\user\AppData\Local\Programs\Python\Python310\lib\site-packages\pymysql\cursors.py", line 310, in _query
    conn.query(q)
  File "C:\Users\user\AppData\Local\Programs\Python\Python310\lib\site-packages\pymysql\connections.py", line 548, in query
    self._affected_rows = self._read_query_result(unbuffered=unbuffered)
  File "C:\Users\user\AppData\Local\Programs\Python\Python310\lib\site-packages\pymysql\connections.py", line 775, in _read_query_result
    result.read()
  File "C:\Users\user\AppData\Local\Programs\Python\Python310\lib\site-packages\pymysql\connections.py", line 1156, in read
    first_packet = self.connection._read_packet()
  File "C:\Users\user\AppData\Local\Programs\Python\Python310\lib\site-packages\pymysql\connections.py", line 725, in _read_packet
    packet.raise_for_error()
  File "C:\Users\user\AppData\Local\Programs\Python\Python310\lib\site-packages\pymysql\protocol.py", line 221, in raise_for_error
    err.raise_mysql_exception(self._data)
  File "C:\Users\user\AppData\Local\Programs\Python\Python310\lib\site-packages\pymysql\err.py", line 143, in raise_mysql_exception
    raise errorclass(errno, errval)
pymysql.err.ProgrammingError: (1064, "You have an error in your SQL syntax; check the manual that corresponds to your MySQL server version for the right syntax to use near 'get = 0 AND used != 1' at line 1")

[2022.12.30/11:22:09] : ERROR | Traceback (most recent call last):
  File "C:\Users\user\code\python\kiosk\BackEnd\sorce\module\DB\DB.py", line 31, in SELECT_ONE
    self.curs.execute(query,args)
  File "C:\Users\user\AppData\Local\Programs\Python\Python310\lib\site-packages\pymysql\cursors.py", line 148, in execute
    result = self._query(query)
  File "C:\Users\user\AppData\Local\Programs\Python\Python310\lib\site-packages\pymysql\cursors.py", line 310, in _query
    conn.query(q)
  File "C:\Users\user\AppData\Local\Programs\Python\Python310\lib\site-packages\pymysql\connections.py", line 548, in query
    self._affected_rows = self._read_query_result(unbuffered=unbuffered)
  File "C:\Users\user\AppData\Local\Programs\Python\Python310\lib\site-packages\pymysql\connections.py", line 775, in _read_query_result
    result.read()
  File "C:\Users\user\AppData\Local\Programs\Python\Python310\lib\site-packages\pymysql\connections.py", line 1156, in read
    first_packet = self.connection._read_packet()
  File "C:\Users\user\AppData\Local\Programs\Python\Python310\lib\site-packages\pymysql\connections.py", line 725, in _read_packet
    packet.raise_for_error()
  File "C:\Users\user\AppData\Local\Programs\Python\Python310\lib\site-packages\pymysql\protocol.py", line 221, in raise_for_error
    err.raise_mysql_exception(self._data)
  File "C:\Users\user\AppData\Local\Programs\Python\Python310\lib\site-packages\pymysql\err.py", line 143, in raise_mysql_exception
    raise errorclass(errno, errval)
pymysql.err.ProgrammingError: (1064, "You have an error in your SQL syntax; check the manual that corresponds to your MySQL server version for the right syntax to use near 'get = 0 AND used != 1' at line 1")

[2022.12.30/11:25:43] : ERROR | Traceback (most recent call last):
  File "c:\Users\user\code\python\kiosk\BackEnd\sorce\module\DB\DB.py", line 31, in SELECT_ONE
    self.curs.execute(query,args)
  File "C:\Users\user\AppData\Local\Programs\Python\Python310\lib\site-packages\pymysql\cursors.py", line 148, in execute
    result = self._query(query)
  File "C:\Users\user\AppData\Local\Programs\Python\Python310\lib\site-packages\pymysql\cursors.py", line 310, in _query
    conn.query(q)
  File "C:\Users\user\AppData\Local\Programs\Python\Python310\lib\site-packages\pymysql\connections.py", line 548, in query
    self._affected_rows = self._read_query_result(unbuffered=unbuffered)
  File "C:\Users\user\AppData\Local\Programs\Python\Python310\lib\site-packages\pymysql\connections.py", line 775, in _read_query_result
    result.read()
  File "C:\Users\user\AppData\Local\Programs\Python\Python310\lib\site-packages\pymysql\connections.py", line 1156, in read
    first_packet = self.connection._read_packet()
  File "C:\Users\user\AppData\Local\Programs\Python\Python310\lib\site-packages\pymysql\connections.py", line 725, in _read_packet
    packet.raise_for_error()
  File "C:\Users\user\AppData\Local\Programs\Python\Python310\lib\site-packages\pymysql\protocol.py", line 221, in raise_for_error
    err.raise_mysql_exception(self._data)
  File "C:\Users\user\AppData\Local\Programs\Python\Python310\lib\site-packages\pymysql\err.py", line 143, in raise_mysql_exception
    raise errorclass(errno, errval)
pymysql.err.ProgrammingError: (1064, "You have an error in your SQL syntax; check the manual that corresponds to your MySQL server version for the right syntax to use near 'get = 0 AND used != 1' at line 1")

[2022.12.30/11:26:47] : ERROR | Traceback (most recent call last):
  File "C:\Users\user\code\python\kiosk\BackEnd\sorce\module\DB\DB.py", line 31, in SELECT_ONE
    self.curs.execute(query,args)
  File "C:\Users\user\AppData\Local\Programs\Python\Python310\lib\site-packages\pymysql\cursors.py", line 148, in execute
    result = self._query(query)
  File "C:\Users\user\AppData\Local\Programs\Python\Python310\lib\site-packages\pymysql\cursors.py", line 310, in _query
    conn.query(q)
  File "C:\Users\user\AppData\Local\Programs\Python\Python310\lib\site-packages\pymysql\connections.py", line 548, in query
    self._affected_rows = self._read_query_result(unbuffered=unbuffered)
  File "C:\Users\user\AppData\Local\Programs\Python\Python310\lib\site-packages\pymysql\connections.py", line 775, in _read_query_result
    result.read()
  File "C:\Users\user\AppData\Local\Programs\Python\Python310\lib\site-packages\pymysql\connections.py", line 1156, in read
    first_packet = self.connection._read_packet()
  File "C:\Users\user\AppData\Local\Programs\Python\Python310\lib\site-packages\pymysql\connections.py", line 725, in _read_packet
    packet.raise_for_error()
  File "C:\Users\user\AppData\Local\Programs\Python\Python310\lib\site-packages\pymysql\protocol.py", line 221, in raise_for_error
    err.raise_mysql_exception(self._data)
  File "C:\Users\user\AppData\Local\Programs\Python\Python310\lib\site-packages\pymysql\err.py", line 143, in raise_mysql_exception
    raise errorclass(errno, errval)
pymysql.err.ProgrammingError: (1064, "You have an error in your SQL syntax; check the manual that corresponds to your MySQL server version for the right syntax to use near 'get = 0 AND used = 0' at line 1")

[2022.12.30/11:27:15] : ERROR | Traceback (most recent call last):
  File "C:\Users\user\code\python\kiosk\BackEnd\sorce\module\DB\DB.py", line 31, in SELECT_ONE
    self.curs.execute(query,args)
  File "C:\Users\user\AppData\Local\Programs\Python\Python310\lib\site-packages\pymysql\cursors.py", line 148, in execute
    result = self._query(query)
  File "C:\Users\user\AppData\Local\Programs\Python\Python310\lib\site-packages\pymysql\cursors.py", line 310, in _query
    conn.query(q)
  File "C:\Users\user\AppData\Local\Programs\Python\Python310\lib\site-packages\pymysql\connections.py", line 548, in query
    self._affected_rows = self._read_query_result(unbuffered=unbuffered)
  File "C:\Users\user\AppData\Local\Programs\Python\Python310\lib\site-packages\pymysql\connections.py", line 775, in _read_query_result
    result.read()
  File "C:\Users\user\AppData\Local\Programs\Python\Python310\lib\site-packages\pymysql\connections.py", line 1156, in read
    first_packet = self.connection._read_packet()
  File "C:\Users\user\AppData\Local\Programs\Python\Python310\lib\site-packages\pymysql\connections.py", line 725, in _read_packet
    packet.raise_for_error()
  File "C:\Users\user\AppData\Local\Programs\Python\Python310\lib\site-packages\pymysql\protocol.py", line 221, in raise_for_error
    err.raise_mysql_exception(self._data)
  File "C:\Users\user\AppData\Local\Programs\Python\Python310\lib\site-packages\pymysql\err.py", line 143, in raise_mysql_exception
    raise errorclass(errno, errval)
pymysql.err.ProgrammingError: (1064, "You have an error in your SQL syntax; check the manual that corresponds to your MySQL server version for the right syntax to use near 'get = 0 AND used = 0' at line 1")

[2022.12.30/11:27:41] : ERROR | Traceback (most recent call last):
  File "C:\Users\user\code\python\kiosk\BackEnd\sorce\module\DB\DB.py", line 31, in SELECT_ONE
    self.curs.execute(query,args)
  File "C:\Users\user\AppData\Local\Programs\Python\Python310\lib\site-packages\pymysql\cursors.py", line 148, in execute
    result = self._query(query)
  File "C:\Users\user\AppData\Local\Programs\Python\Python310\lib\site-packages\pymysql\cursors.py", line 310, in _query
    conn.query(q)
  File "C:\Users\user\AppData\Local\Programs\Python\Python310\lib\site-packages\pymysql\connections.py", line 548, in query
    self._affected_rows = self._read_query_result(unbuffered=unbuffered)
  File "C:\Users\user\AppData\Local\Programs\Python\Python310\lib\site-packages\pymysql\connections.py", line 775, in _read_query_result
    result.read()
  File "C:\Users\user\AppData\Local\Programs\Python\Python310\lib\site-packages\pymysql\connections.py", line 1156, in read
    first_packet = self.connection._read_packet()
  File "C:\Users\user\AppData\Local\Programs\Python\Python310\lib\site-packages\pymysql\connections.py", line 725, in _read_packet
    packet.raise_for_error()
  File "C:\Users\user\AppData\Local\Programs\Python\Python310\lib\site-packages\pymysql\protocol.py", line 221, in raise_for_error
    err.raise_mysql_exception(self._data)
  File "C:\Users\user\AppData\Local\Programs\Python\Python310\lib\site-packages\pymysql\err.py", line 143, in raise_mysql_exception
    raise errorclass(errno, errval)
pymysql.err.ProgrammingError: (1064, "You have an error in your SQL syntax; check the manual that corresponds to your MySQL server version for the right syntax to use near 'get = 0, used = 0)' at line 1")

[2022.12.30/11:28:32] : ERROR | Traceback (most recent call last):
  File "C:\Users\user\code\python\kiosk\BackEnd\sorce\module\DB\DB.py", line 31, in SELECT_ONE
    self.curs.execute(query,args)
  File "C:\Users\user\AppData\Local\Programs\Python\Python310\lib\site-packages\pymysql\cursors.py", line 148, in execute
    result = self._query(query)
  File "C:\Users\user\AppData\Local\Programs\Python\Python310\lib\site-packages\pymysql\cursors.py", line 310, in _query
    conn.query(q)
  File "C:\Users\user\AppData\Local\Programs\Python\Python310\lib\site-packages\pymysql\connections.py", line 548, in query
    self._affected_rows = self._read_query_result(unbuffered=unbuffered)
  File "C:\Users\user\AppData\Local\Programs\Python\Python310\lib\site-packages\pymysql\connections.py", line 775, in _read_query_result
    result.read()
  File "C:\Users\user\AppData\Local\Programs\Python\Python310\lib\site-packages\pymysql\connections.py", line 1156, in read
    first_packet = self.connection._read_packet()
  File "C:\Users\user\AppData\Local\Programs\Python\Python310\lib\site-packages\pymysql\connections.py", line 725, in _read_packet
    packet.raise_for_error()
  File "C:\Users\user\AppData\Local\Programs\Python\Python310\lib\site-packages\pymysql\protocol.py", line 221, in raise_for_error
    err.raise_mysql_exception(self._data)
  File "C:\Users\user\AppData\Local\Programs\Python\Python310\lib\site-packages\pymysql\err.py", line 143, in raise_mysql_exception
    raise errorclass(errno, errval)
pymysql.err.ProgrammingError: (1064, "You have an error in your SQL syntax; check the manual that corresponds to your MySQL server version for the right syntax to use near 'get = 0 AND used = 0' at line 1")

[2022.12.30/11:31:52] : ERROR | Traceback (most recent call last):
  File "C:\Users\user\code\python\kiosk\BackEnd\sorce\module\DB\DB.py", line 31, in SELECT_ONE
    self.curs.execute(query,args)
  File "C:\Users\user\AppData\Local\Programs\Python\Python310\lib\site-packages\pymysql\cursors.py", line 148, in execute
    result = self._query(query)
  File "C:\Users\user\AppData\Local\Programs\Python\Python310\lib\site-packages\pymysql\cursors.py", line 310, in _query
    conn.query(q)
  File "C:\Users\user\AppData\Local\Programs\Python\Python310\lib\site-packages\pymysql\connections.py", line 548, in query
    self._affected_rows = self._read_query_result(unbuffered=unbuffered)
  File "C:\Users\user\AppData\Local\Programs\Python\Python310\lib\site-packages\pymysql\connections.py", line 775, in _read_query_result
    result.read()
  File "C:\Users\user\AppData\Local\Programs\Python\Python310\lib\site-packages\pymysql\connections.py", line 1156, in read
    first_packet = self.connection._read_packet()
  File "C:\Users\user\AppData\Local\Programs\Python\Python310\lib\site-packages\pymysql\connections.py", line 725, in _read_packet
    packet.raise_for_error()
  File "C:\Users\user\AppData\Local\Programs\Python\Python310\lib\site-packages\pymysql\protocol.py", line 221, in raise_for_error
    err.raise_mysql_exception(self._data)
  File "C:\Users\user\AppData\Local\Programs\Python\Python310\lib\site-packages\pymysql\err.py", line 143, in raise_mysql_exception
    raise errorclass(errno, errval)
pymysql.err.ProgrammingError: (1064, "You have an error in your SQL syntax; check the manual that corresponds to your MySQL server version for the right syntax to use near 'get = 0 AND used = 0' at line 1")

[2022.12.30/11:36:46] : ERROR | Traceback (most recent call last):
  File "C:\Users\user\code\python\kiosk\BackEnd\sorce\module\DB\DB.py", line 31, in SELECT_ONE
    self.curs.execute(query,args)
  File "C:\Users\user\AppData\Local\Programs\Python\Python310\lib\site-packages\pymysql\cursors.py", line 148, in execute
    result = self._query(query)
  File "C:\Users\user\AppData\Local\Programs\Python\Python310\lib\site-packages\pymysql\cursors.py", line 310, in _query
    conn.query(q)
  File "C:\Users\user\AppData\Local\Programs\Python\Python310\lib\site-packages\pymysql\connections.py", line 548, in query
    self._affected_rows = self._read_query_result(unbuffered=unbuffered)
  File "C:\Users\user\AppData\Local\Programs\Python\Python310\lib\site-packages\pymysql\connections.py", line 775, in _read_query_result
    result.read()
  File "C:\Users\user\AppData\Local\Programs\Python\Python310\lib\site-packages\pymysql\connections.py", line 1156, in read
    first_packet = self.connection._read_packet()
  File "C:\Users\user\AppData\Local\Programs\Python\Python310\lib\site-packages\pymysql\connections.py", line 725, in _read_packet
    packet.raise_for_error()
  File "C:\Users\user\AppData\Local\Programs\Python\Python310\lib\site-packages\pymysql\protocol.py", line 221, in raise_for_error
    err.raise_mysql_exception(self._data)
  File "C:\Users\user\AppData\Local\Programs\Python\Python310\lib\site-packages\pymysql\err.py", line 143, in raise_mysql_exception
    raise errorclass(errno, errval)
pymysql.err.OperationalError: (1046, 'No database selected')

